Workbook

Sheet Raw Data
A1: Name | B1: Source | C1: Age Band | D1: Gender | E1: Years Playing (est) | F1: Experience Band | G1: Skill (self-described) | H1: Life Stage | I1: New to / returning to SG | J1: Has Reliable Group | K1: OK with Strangers | L1: Has Hosted or Booked | M1: Knows Meetup | N1: Knows ReClub | O1: Where Apps Failed Them | P1: Pain Points | Q1: Friendliness > Skill | R1: Demand Tier (1-5) | S1: Demand Label | T1: Channels Used | U1: Notes
A2: Vickson | B2: Friend | C2: 20-29 | D2: M | F2: Unknown | G2: Unknown | H2: Unknown | I2: No | J2: Yes | K2: Unknown | L2: Unknown | M2: Unknown | N2: Unknown | P2: None recorded | R2: 1 | S2: 1 - No need | T2: Friends/own circle | U2: Won't use himself (friends already invite him) but thinks many would; would use if he and a friend were looking for a game
A3: Jen Yaw | B3: Friend | C3: 40+ | D3: M | F3: Unknown | G3: Unknown | H3: Working | I3: No | J3: Yes | K3: Unknown | L3: Unknown | M3: Unknown | N3: Unknown | P3: None recorded | R3: 1 | S3: 1 - No need | T3: WhatsApp; Friends/own circle | U3: SPH WhatsApp group always finds 14+ players; no need to look outside
A4: Elliot | B4: Friend | C4: Under 20 | D4: M | F4: Unknown | G4: Unknown | H4: Unknown | I4: No | J4: Yes | K4: Unknown | L4: Unknown | M4: Unknown | N4: Unknown | P4: Vague skill standards; Timing mismatch; Location inconvenient | R4: 1 | S4: 1 - No need | T4: Telegram; Friends/own circle | U4: Liked court-reselling idea most; joined a tele game once, standards vague, never returned (has own games)
A5: Shocked face | B5: Telegram | C5: 20-29 | D5: F | E5: 10 | F5: 10+ yrs | G5: High beginner | H5: Unknown | I5: No | J5: Yes | K5: Unknown | L5: Yes | M5: Unknown | N5: Unknown | P5: Vague skill standards; Court booking barriers; Not enough players for 12 | R5: 1 | S5: 1 - No need | T5: Telegram; Friends/own circle | U5: Finds players internally; 'no need for volleyball apps for now' but 'hard to fix these chats unless you create an app'; intermediate range is a huge self-rated grey area; courts hard to book on ActiveSG
A6: nat | B6: Reddit | C6: 20-29 | D6: F | E6: 2 | F6: 1-3 yrs | G6: Rusty | H6: Student | I6: No | J6: No | K6: Yes | L6: Unknown | M6: Unknown | N6: Unknown | P6: Timing mismatch; No friends who play; Hard to find games | Q6: Yes | R6: 3 | S6: 3 - Interested | T6: Reddit; Telegram; Friends/own circle | U6: Hall team season over, teammates busy; tele games fall on unavailable days; friendliness > skill; prefers indoor, own age, more girls
A7: Isaac | B7: Reddit | C7: 20-29 | D7: M | E7: 1 | F7: 1-3 yrs | G7: Casual | H7: Unknown | I7: No | J7: Yes | K7: Yes | L7: Yes | M7: Yes | N7: No | O7: Meetup has very few volleyball games | P7: Not enough players for 12; Vague skill standards; Apps lack volleyball games | R7: 3 | S7: 3 - Interested | T7: Friends/own circle; Meetup | U7: Organises games, recruits randoms when short of 12 but skill levels differ; plays ActiveSG/NTU courts
A8: Eric Siow | B8: Reddit | C8: 40+ | D8: M | F8: Unknown | G8: High beginner-Intermediate | H8: Working | I8: No | J8: Yes | K8: Yes | L8: Unknown | M8: Unknown | N8: Yes | P8: Group chats inactive/invite-only | R8: 2 | S8: 2 - Low need | T8: Telegram; WhatsApp; ReClub | U8: Asked to join Saturday tele games, no replies; finds games every weekend via tele-to-private-WhatsApp pipeline
A9: Rizzy Izzy | B9: Reddit | C9: Under 20 | D9: M | E9: 1.5 | F9: 1-3 yrs | G9: Intermediate | H9: Student | I9: No | J9: No | K9: Yes | L9: No | M9: No | N9: No | P9: Hard to find games; Not enough players for 12; Group chats inactive/invite-only; Court booking barriers | R9: 4 | S9: 4 - Said would use | T9: Reddit; Telegram | U9: 3 keen friends but can't reach 12; existing groups feel closed to strangers; scared to book courts (no-shows, no way to prove his level); wants player photos; never knew volleyball apps existed
A10: Hao Kai | B10: Reddit | C10: 20-29 | D10: M | E10: 4 | F10: 4-9 yrs | G10: Intermediate | H10: Unknown | I10: No | J10: Yes | K10: Yes | L10: Unknown | M10: Yes | N10: Yes | O10: Games conditional: net height, fees, pax, skill level | P10: Hard to find games; Vague skill standards; Timing mismatch; Court booking barriers | R10: 3 | S10: 3 - Interested | T10: Telegram; ReClub; Meetup; Friends/own circle | U10: Uses everything frequently, still struggles; agrees skill self-definition is hard
A11: Bo Xian | B11: Reddit | C11: 20-29 | D11: M | E11: 0 | F11: Never played | G11: Never played | H11: Unknown | I11: No | J11: No | K11: Yes | L11: Unknown | M11: No | N11: No | P11: Beginner-unfriendly scene; No friends who play; Hard to find games | R11: 3 | S11: 3 - Interested | T11: Google; Reddit | U11: Wants to start; only finds competitive communities; introverted, wants to learn + meet people 20-30; Aidan's Reddit post was first relevant Google result
A12: Wei Liang | B12: Reddit | C12: 40+ | D12: M | E12: 20 | F12: 10+ yrs | G12: Leisure (ex-school) | H12: Unknown | I12: No | J12: Yes | K12: Yes | L12: Unknown | M12: Unknown | N12: Unknown | P12: None recorded | R12: 2 | S12: 2 - Low need | T12: Friends/own circle | U12: 20 years playing, own usual groups; 'no harm joining more groups'
A13: shawn | B13: Reddit | C13: 30-39 | D13: M | E13: 10 | F13: 10+ yrs | G13: Amateur | H13: Unknown | I13: No | J13: No | K13: Yes | L13: Unknown | M13: Yes | N13: Yes | O13: Games exist but timing doesn't match his availability | P13: No friends who play; Timing mismatch; Hard to find games | Q13: Yes | R13: 4 | S13: 4 - Said would use | T13: Reddit; ReClub; Meetup | U13: Friends don't play volleyball; started using ReClub/Meetup actively after asking for recommendations; wants more games + friendly people; 'if the group is chill it will be alright'
A14: V | B14: Reddit | C14: 30-39 | D14: M | F14: Unknown | G14: Unknown | H14: Working | I14: Yes | J14: No | K14: Yes | L14: Unknown | M14: No | N14: No | P14: No friends who play; Hard to find games | R14: 4 | S14: 4 - Said would use | T14: Reddit | U14: Filipino working in SG, no friends here; used Facebook groups in PH; 'app is like an all-in-one... good for people navigating new places'
A15: B | B15: Reddit | C15: 30-39 | D15: M | F15: Unknown | G15: Lapsed (ex-ITE team) | H15: Working | I15: No | J15: No | K15: Unknown | L15: Unknown | M15: Unknown | N15: Unknown | P15: No friends who play; Hard to find games | R15: 3 | S15: 3 - Interested | T15: Reddit | U15: Everyone working, hard to organise; hasn't played in years
A16: Fabian | B16: Reddit | C16: Unknown | D16: Unknown | E16: 0.2 | F16: <1 yr | G16: Beginner | H16: Unknown | I16: No | J16: Yes | K16: Unknown | L16: Unknown | M16: Unknown | N16: Unknown | P16: None recorded | S16: Unknown | T16: Friends/own circle | U16: 2 months in, plays with friends; didn't reply follow-up
A17: - (25F) | B17: Reddit | C17: 20-29 | D17: F | E17: 6 | F17: 4-9 yrs | G17: Rusty | H17: Between jobs | I17: No | J17: Yes | K17: Yes | L17: Yes | M17: Unknown | N17: Unknown | P17: Indoor courts scarce; Hard to find games | R17: 3 | S17: 3 - Interested | T17: Reddit; Friends/own circle | U17: Played age 10-16; peppers at HDB with 2 friends; found a group but it books outdoor MOE Evans (very hot before 6.30pm); wants indoor
A18: Claire Lim | B18: Reddit | C18: Under 20 | D18: F | E18: 3.5 | F18: 4-9 yrs | G18: School team | H18: Student | I18: Yes | J18: No | K18: Yes | L18: Unknown | M18: Yes | N18: Unknown | O18: Meetup requires age 18+ | P18: No friends who play; Hard to find games | R18: 4 | S18: 4 - Said would use | T18: Reddit | U18: Back from Taiwan, no friends/relatives who play in SG; blocked from Meetup by 18+ rule; 'would absolutely use' the app
A19: L | B19: Reddit | C19: 30-39 | D19: F | E19: 15 | F19: 10+ yrs | G19: Lapsed (injury) | H19: Unknown | I19: No | J19: No | K19: Yes | L19: Unknown | M19: Unknown | N19: Unknown | P19: Hard to find games; Beginner-unfriendly scene | R19: 4 | S19: 4 - Said would use | T19: Reddit | U19: Played primary school to mid-20s, stopped from wrist nerve damage; wants beginner/less-professional group to restart; 'well needed, would definitely use'
A20: Dong | B20: Reddit | C20: 20-29 | D20: M | E20: 4 | F20: 4-9 yrs | G20: Casual (ex-school) | H20: Unknown | I20: No | J20: Yes | K20: Yes | L20: Unknown | M20: Yes | N20: Yes | O20: Both apps quite inactive or invite-only | P20: Timing mismatch; Group chats inactive/invite-only; Hard to find games | R20: 5 | S20: 5 - Joined waitlist unprompted | T20: Telegram; Reddit; ReClub; Meetup | U20: One tele group, can't always meet its timings; ReClub/Meetup 'nothing much', inactive or invite-only; joined waitlist unprompted, 'can't wait for it to come out'
A21: Y | B21: Reddit | C21: 20-29 | D21: F | E21: 0 | F21: Never played | G21: Complete beginner | H21: Unknown | I21: No | J21: No | K21: Unknown | L21: Unknown | M21: No | N21: No | P21: Beginner-unfriendly scene; Hard to find games | R21: 3 | S21: 3 - Interested | T21: Reddit | U21: Scouting for a beginner friend (needs indoor); assumes experienced players reject newbies; never knew sports apps existed; said waitlist site 'looks very legit'
A22: H | B22: Reddit | C22: 20-29 | D22: M | F22: Unknown | G22: Casual | H22: Unknown | I22: No | J22: Yes | K22: Yes | L22: No | M22: No | N22: No | P22: None recorded | R22: 3 | S22: 3 - Interested | T22: Reddit; ASIG | U22: Plays ~monthly + ASIG; never hosts because 'too lazy to find', just joins others' games; only Reddit otherwise
A23: j | B23: Reddit | C23: Under 20 | D23: M | E23: 0.5 | F23: <1 yr | G23: Beginner | H23: Unknown | I23: No | J23: Yes | K23: Unknown | L23: No | M23: No | N23: No | P23: Indoor courts scarce; Court booking barriers; Hard to find games | R23: 3 | S23: 3 - Interested | T23: Reddit; Friends/own circle | U23: Friends only play beach, he wants indoor; never hosted, doesn't know the booking process; never heard of ReClub/Meetup, willing to try
A24: Jun Karn | B24: Reddit | C24: 30-39 | D24: M | E24: 0 | F24: Never played | G24: Never played | H24: Unknown | I24: No | J24: No | K24: Unknown | L24: Unknown | M24: Unknown | N24: Unknown | P24: Beginner-unfriendly scene; No friends who play; Hard to find games | R24: 3 | S24: 3 - Interested | T24: Reddit | U24: Never played sports growing up, wants to learn basics; no friends to play with
A25: Chad | B25: Reddit | C25: 30-39 | D25: M | E25: 3.5 | F25: 4-9 yrs | G25: Rusty (setter/libero) | H25: Student | I25: Yes | J25: No | K25: Unknown | L25: Unknown | M25: Yes | N25: No | O25: Meetup shows only classes, no games near Clarke Quay/Chinatown | P25: No friends who play; Hard to find games; Apps lack volleyball games; Location inconvenient | R25: 3 | S25: 3 - Interested | T25: Reddit; Meetup | U25: Filipino via Dubai, in SG 1 month for studies; classmates don't play; never heard of ReClub
A26: ezragoh | B26: Reddit | C26: 20-29 | D26: M | E26: 0.4 | F26: <1 yr | G26: Beginner (club) | H26: Unknown | I26: No | J26: Yes | K26: Yes | L26: No | M26: Yes | N26: Unknown | O26: Meetup times and locations don't suit him | P26: Timing mismatch; Location inconvenient; Court booking barriers | R26: 3 | S26: 3 - Interested | T26: Meetup; Friends/own circle | U26: In Volleyball Ace club; never books courts (money + admin work); would host if profit > $50
A27: Braxton | B27: Reddit | C27: 20-29 | D27: M | E27: 1 | F27: 1-3 yrs | G27: Casual | H27: Student | I27: Yes | J27: No | K27: Yes | L27: No | M27: Unknown | N27: Unknown | P27: Hard to find games | R27: 4 | S27: 4 - Said would use | T27: Reddit | U27: Started in Sydney (club socials everywhere), back in SG for a month; tough to find socials here; referred to Aidan by an Australia teammate; down to host; 'would definitely use'
A28: Perry Chang | B28: Reddit | C28: 30-39 | D28: M | E28: 1 | F28: 1-3 yrs | G28: Beginner | H28: Unknown | I28: No | J28: Yes | K28: Unknown | L28: No | M28: No | N28: No | P28: Court booking barriers; Timing mismatch; Hard to find games | R28: 3 | S28: 3 - Interested | T28: Reddit; XHS | U28: Plays to accompany girlfriend (recreational ex-school-team); tried Xiao Hong Shu, no results; won't book courts, fears wasting money if headcount falls short; asked if Aidan represents ReClub
A29: A | B29: Reddit | C29: 20-29 | D29: M | E29: 4 | F29: 4-9 yrs | G29: Recreational (lapsed) | H29: NS | I29: No | J29: No | K29: Yes | L29: No | M29: No | N29: No | P29: Hard to find games | R29: 3 | S29: 3 - Interested | T29: Reddit | U29: Played 2020-2024, in NS now, restarting; never heard of ReClub/Meetup; organising 'isn't his thing'
A30: Wookie | B30: Reddit | C30: 20-29 | D30: M | E30: 1 | F30: 1-3 yrs | G30: Returner (low skill) | H30: Unknown | I30: No | J30: No | K30: Yes | L30: No | M30: Unknown | N30: Unknown | P30: Beginner-unfriendly scene; Hard to find games; No friends who play; Timing mismatch; Court booking barriers | R30: 3 | S30: 3 - Interested | T30: Reddit; Telegram | U30: In 2 weeks only 1 beginner game appeared in the tele group and he was unavailable; never booked, 'never knew the community'; friends don't play
A31: mc | B31: Reddit | C31: 30-39 | D31: M | E31: 0 | F31: Never played | G31: Never played | H31: Unknown | I31: No | J31: No | K31: Yes | L31: Unknown | M31: Yes | N31: Yes | O31: ReClub has zero volleyball games; Meetup wants intermediate or offers classes only | P31: Hard to find games; Beginner-unfriendly scene; Apps lack volleyball games | Q31: Yes | R31: 4 | S31: 4 - Said would use | T31: Reddit; ReClub; Meetup | U31: Wants to start because of Haikyuu; attitude > skill ('unfriendliness is hard to change'); would use the app to join games

Sheet Dashboard
A1: COTERIE — CUSTOMER DISCOVERY DASHBOARD
A2: 30 interviews · Jul 2026 · Friends (3), Telegram (1), Reddit (26)
A4: READ THIS FIRST — WHAT THE DATA SAYS
A5: 1. TARGET USER: people WITHOUT a reliable group. Everyone who said 'no need' already has one. Strongest demand: newcomers/returners to SG, lapsed players restarting, and complete beginners.
A6: 2. POSITIONING: 'find a game you can actually join' beats 'organise volleyball'. Top pains are finding games, beginner-unfriendliness, and closed/inactive group chats — not scheduling tools.
A7: 3. SUPPLY RISK: almost everyone wants to JOIN games; only 3 of 30 have ever hosted or booked. Barriers: cost risk, admin, credibility, not knowing the process. Solve hosting or you have demand with no inventory.
A8: 4. COMPETITION IS WEAK: Meetup/ReClub are unknown to most, and everyone who tried them found no usable volleyball games (classes only, 18+ wall, inactive, wrong level).
A9: 5. BUILD SIGNAL: 7 of 30 said they'd use it, 1 joined the waitlist unprompted — plus your 50+ silent waitlist signups (not interviewed, not in these numbers).
A11: A. DEMAND VALIDATION | F11: B. WHO YOUR USER IS
A13: Demand tiers (each person coded once) | F13: Age bands
A14: Tier | B14: People | C14: % | F14: Age | G14: People | H14: %
A15: 1 - No need | B15: =COUNTIF('Raw Data'!$R$2:$R$31,1) -> 4 | C15: =B15/COUNTA('Raw Data'!$A$2:$A$31) -> 0.13333333 | F15: Under 20 | G15: =COUNTIF('Raw Data'!$C$2:$C$31,"Under 20") -> 4 | H15: =G15/COUNTA('Raw Data'!$A$2:$A$31) -> 0.13333333
A16: 2 - Low need | B16: =COUNTIF('Raw Data'!$R$2:$R$31,2) -> 2 | C16: =B16/COUNTA('Raw Data'!$A$2:$A$31) -> 0.066666667 | F16: 20-29 | G16: =COUNTIF('Raw Data'!$C$2:$C$31,"20-29") -> 14 | H16: =G16/COUNTA('Raw Data'!$A$2:$A$31) -> 0.46666667
A17: 3 - Interested | B17: =COUNTIF('Raw Data'!$R$2:$R$31,3) -> 15 | C17: =B17/COUNTA('Raw Data'!$A$2:$A$31) -> 0.5 | F17: 30-39 | G17: =COUNTIF('Raw Data'!$C$2:$C$31,"30-39") -> 8 | H17: =G17/COUNTA('Raw Data'!$A$2:$A$31) -> 0.26666667
A18: 4 - Said would use | B18: =COUNTIF('Raw Data'!$R$2:$R$31,4) -> 7 | C18: =B18/COUNTA('Raw Data'!$A$2:$A$31) -> 0.23333333 | F18: 40+ | G18: =COUNTIF('Raw Data'!$C$2:$C$31,"40+") -> 3 | H18: =G18/COUNTA('Raw Data'!$A$2:$A$31) -> 0.1
A19: 5 - Joined waitlist unprompted | B19: =COUNTIF('Raw Data'!$R$2:$R$31,5) -> 1 | C19: =B19/COUNTA('Raw Data'!$A$2:$A$31) -> 0.033333333 | F19: Unknown | G19: =COUNTIF('Raw Data'!$C$2:$C$31,"Unknown") -> 1 | H19: =G19/COUNTA('Raw Data'!$A$2:$A$31) -> 0.033333333
A20: Unknown (no reply) | B20: =COUNTA('Raw Data'!$A$2:$A$31)-COUNT('Raw Data'!$R$2:$R$31) -> 1 | C20: =B20/COUNTA('Raw Data'!$A$2:$A$31) -> 0.033333333
A21: Positive signal (tier 3+) | B21: =COUNTIF('Raw Data'!$R$2:$R$31,">=3")/COUNTA('Raw Data'!$A$2:$A$31) -> 0.76666667 | D21: excludes your 50+ waitlist signups | F21: Gender
F22: Gender | G22: People | H22: %
A23: Demand by source (avg tier, 1-5) | F23: Male | G23: =COUNTIF('Raw Data'!$D$2:$D$31,"M") -> 23 | H23: =G23/COUNTA('Raw Data'!$A$2:$A$31) -> 0.76666667
A24: Source | B24: Avg tier | F24: Female | G24: =COUNTIF('Raw Data'!$D$2:$D$31,"F") -> 6 | H24: =G24/COUNTA('Raw Data'!$A$2:$A$31) -> 0.2
A25: Friend | B25: =IFERROR(AVERAGEIFS('Raw Data'!$R$2:$R$31,'Raw Data'!$B$2:$B$31,"Friend"),"n/a") -> 1 | F25: Unknown | G25: =COUNTIF('Raw Data'!$D$2:$D$31,"Unknown") -> 1 | H25: =G25/COUNTA('Raw Data'!$A$2:$A$31) -> 0.033333333
A26: Telegram | B26: =IFERROR(AVERAGEIFS('Raw Data'!$R$2:$R$31,'Raw Data'!$B$2:$B$31,"Telegram"),"n/a") -> 1
A27: Reddit | B27: =IFERROR(AVERAGEIFS('Raw Data'!$R$2:$R$31,'Raw Data'!$B$2:$B$31,"Reddit"),"n/a") -> 3.28 | F27: Experience (years playing, estimated)
A28: Avg tier: has reliable group | B28: =AVERAGEIFS('Raw Data'!$R$2:$R$31,'Raw Data'!$J$2:$J$31,"Yes") -> 2.4285714 | F28: Experience | G28: People | H28: %
A29: Avg tier: NO reliable group | B29: =AVERAGEIFS('Raw Data'!$R$2:$R$31,'Raw Data'!$J$2:$J$31,"No") -> 3.4666667 | D29: the gap here is your targeting answer | F29: Never played | G29: =COUNTIF('Raw Data'!$F$2:$F$31,"Never played") -> 4 | H29: =G29/COUNTA('Raw Data'!$A$2:$A$31) -> 0.13333333
F30: <1 yr | G30: =COUNTIF('Raw Data'!$F$2:$F$31,"<1 yr") -> 3 | H30: =G30/COUNTA('Raw Data'!$A$2:$A$31) -> 0.1
A31: Competitor awareness | F31: 1-3 yrs | G31: =COUNTIF('Raw Data'!$F$2:$F$31,"1-3 yrs") -> 6 | H31: =G31/COUNTA('Raw Data'!$A$2:$A$31) -> 0.2
A32: Awareness | B32: People | C32: % | F32: 4-9 yrs | G32: =COUNTIF('Raw Data'!$F$2:$F$31,"4-9 yrs") -> 6 | H32: =G32/COUNTA('Raw Data'!$A$2:$A$31) -> 0.2
A33: Knows Meetup | B33: =COUNTIF('Raw Data'!$M$2:$M$31,"Yes") -> 8 | C33: =B33/COUNTA('Raw Data'!$A$2:$A$31) -> 0.26666667 | F33: 10+ yrs | G33: =COUNTIF('Raw Data'!$F$2:$F$31,"10+ yrs") -> 4 | H33: =G33/COUNTA('Raw Data'!$A$2:$A$31) -> 0.13333333
A34: Knows ReClub | B34: =COUNTIF('Raw Data'!$N$2:$N$31,"Yes") -> 5 | C34: =B34/COUNTA('Raw Data'!$A$2:$A$31) -> 0.16666667 | F34: Unknown | G34: =COUNTIF('Raw Data'!$F$2:$F$31,"Unknown") -> 7 | H34: =G34/COUNTA('Raw Data'!$A$2:$A$31) -> 0.23333333
A35: Explicitly never heard of either | B35: =COUNTIFS('Raw Data'!$M$2:$M$31,"No",'Raw Data'!$N$2:$N$31,"No") -> 8 | C35: =B35/COUNTA('Raw Data'!$A$2:$A$31) -> 0.26666667 | F35: New to / returning to SG | G35: =COUNTIF('Raw Data'!$I$2:$I$31,"Yes")/COUNTA('Raw Data'!$A$2:$A$31) -> 0.13333333 | I35: V, Chad, Braxton, Claire — all high-demand
A36: Tried an app & it failed them | B36: =SUMPRODUCT(--('Raw Data'!$O$2:$O$31<>"")) -> 8 | C36: =B36/COUNTA('Raw Data'!$A$2:$A$31) -> 0.26666667 | F36: Complete beginners or rusty returners | G36: =SUMPRODUCT(--ISNUMBER(SEARCH("never played",'Raw Data'!$F$2:$F$31)))+SUMPRODUCT(--ISNUMBER(SEARCH("rusty",'Raw Data'!$G$2:$G$31)))+SUMPRODUCT(--ISNUMBER(SEARCH("lapsed",'Raw Data'!$G$2:$G$31)))+SUMPRODUCT(--ISNUMBER(SEARCH("returner",'Raw Data'!$G$2:$G$31))) -> 11 | I36: an undersupplied game type
A37: Failure reasons: few/no volleyball games, classes only, 18+ age wall, inactive or invite-only, wrong skill tier, bad timing/location.
F38: C. PAIN POINTS, RANKED
A39: App awareness (mutually exclusive, for pie)
A40: Awareness (exclusive) | B40: People | C40: % | F40: Pain point | G40: Mentions | H40: % of 30
A41: Knows at least one app | B41: =SUMPRODUCT(--((('Raw Data'!$M$2:$M$31="Yes")+('Raw Data'!$N$2:$N$31="Yes"))>0)) -> 9 | C41: =B41/COUNTA('Raw Data'!$A$2:$A$31) -> 0.3 | F41: Hard to find games | G41: =SUMPRODUCT(--ISNUMBER(SEARCH("Hard to find games",'Raw Data'!$P$2:$P$31))) -> 20 | H41: =G41/COUNTA('Raw Data'!$A$2:$A$31) -> 0.66666667
A42: Explicitly knows neither | B42: =COUNTIFS('Raw Data'!$M$2:$M$31,"No",'Raw Data'!$N$2:$N$31,"No") -> 8 | C42: =B42/COUNTA('Raw Data'!$A$2:$A$31) -> 0.26666667 | F42: No friends who play | G42: =SUMPRODUCT(--ISNUMBER(SEARCH("No friends who play",'Raw Data'!$P$2:$P$31))) -> 9 | H42: =G42/COUNTA('Raw Data'!$A$2:$A$31) -> 0.3
A43: Not asked / unclear | B43: =COUNTA('Raw Data'!$A$2:$A$31)-B41-B42 -> 13 | C43: =B43/COUNTA('Raw Data'!$A$2:$A$31) -> 0.43333333 | F43: Timing mismatch | G43: =SUMPRODUCT(--ISNUMBER(SEARCH("Timing mismatch",'Raw Data'!$P$2:$P$31))) -> 8 | H43: =G43/COUNTA('Raw Data'!$A$2:$A$31) -> 0.26666667
...

Sheet Charts
A1: COTERIE — CHARTS
A2: All charts read live from the Dashboard tables. Pies are only used where categories don't overlap; channels & awareness are multi-select (one person can appear in several), so those stay as bars.
